Workbook

Sheet Dashboard
A1: Mofawtar Q2 Executive Dashboard
A2: Sample quarter: Meta Ads → Prospects → MQL → SQL → Deals → Revenue → ROAS.
A4: Spend | B4: =SUM('05_Daily_Funnel'!C5:C95) | D4: Funnel Conversion
A5: CRM Leads | B5: =SUM('05_Daily_Funnel'!E5:E95) | D5: Lead → MQL | E5: =IFERROR(B7/B6,0)
A6: MQL | B6: =SUM('05_Daily_Funnel'!F5:F95) | D6: MQL → SQL | E6: =IFERROR(B8/B7,0)
A7: SQL | B7: =SUM('05_Daily_Funnel'!G5:G95) | D7: SQL → Deal | E7: =IFERROR(B9/B8,0)
A8: Deals Won | B8: =SUM('05_Daily_Funnel'!H5:H95) | D8: Overall Lead → Deal | E8: =IFERROR(B9/B6,0)
A9: Revenue | B9: =SUM('05_Daily_Funnel'!J5:J95) | D9: SLA Met % | E9: =IFERROR(SUMPRODUCT('05_Daily_Funnel'!E5:E95,'05_Daily_Funnel'!Q5:Q95)/B6,0)
A10: ROAS | B10: =IFERROR(B10/B5,0)
A11: CAC | B11: =IFERROR(B5/B9,0)
A14: Campaign Comparison
A15: Campaign | B15: Spend | C15: Leads | D15: Deals | E15: Revenue | F15: ROAS
A16: In2out - MessCampaign#1 - Testing - 15/4 | B16: =SUMIFS('07_Campaign_Summary'!$C:$C,'07_Campaign_Summary'!$A:$A,"CMP-001") | C16: =SUMIFS('07_Campaign_Summary'!$E:$E,'07_Campaign_Summary'!$A:$A,"CMP-001") | D16: =SUMIFS('07_Campaign_Summary'!$H:$H,'07_Campaign_Summary'!$A:$A,"CMP-001") | E16: =SUMIFS('07_Campaign_Summary'!$J:$J,'07_Campaign_Summary'!$A:$A,"CMP-001") | F16: =SUMIFS('07_Campaign_Summary'!$O:$O,'07_Campaign_Summary'!$A:$A,"CMP-001")
A17: In2out - MessCampaign#2 - Testing - 20/4 | B17: =SUMIFS('07_Campaign_Summary'!$C:$C,'07_Campaign_Summary'!$A:$A,"CMP-002") | C17: =SUMIFS('07_Campaign_Summary'!$E:$E,'07_Campaign_Summary'!$A:$A,"CMP-002") | D17: =SUMIFS('07_Campaign_Summary'!$H:$H,'07_Campaign_Summary'!$A:$A,"CMP-002") | E17: =SUMIFS('07_Campaign_Summary'!$J:$J,'07_Campaign_Summary'!$A:$A,"CMP-002") | F17: =SUMIFS('07_Campaign_Summary'!$O:$O,'07_Campaign_Summary'!$A:$A,"CMP-002")
A18: Mofawtar - E-Receipt - Awareness - Q2 | B18: =SUMIFS('07_Campaign_Summary'!$C:$C,'07_Campaign_Summary'!$A:$A,"CMP-003") | C18: =SUMIFS('07_Campaign_Summary'!$E:$E,'07_Campaign_Summary'!$A:$A,"CMP-003") | D18: =SUMIFS('07_Campaign_Summary'!$H:$H,'07_Campaign_Summary'!$A:$A,"CMP-003") | E18: =SUMIFS('07_Campaign_Summary'!$J:$J,'07_Campaign_Summary'!$A:$A,"CMP-003") | F18: =SUMIFS('07_Campaign_Summary'!$O:$O,'07_Campaign_Summary'!$A:$A,"CMP-003")
A19: Mofawtar - Tax Invoice - Lead Gen - Q2 | B19: =SUMIFS('07_Campaign_Summary'!$C:$C,'07_Campaign_Summary'!$A:$A,"CMP-004") | C19: =SUMIFS('07_Campaign_Summary'!$E:$E,'07_Campaign_Summary'!$A:$A,"CMP-004") | D19: =SUMIFS('07_Campaign_Summary'!$H:$H,'07_Campaign_Summary'!$A:$A,"CMP-004") | E19: =SUMIFS('07_Campaign_Summary'!$J:$J,'07_Campaign_Summary'!$A:$A,"CMP-004") | F19: =SUMIFS('07_Campaign_Summary'!$O:$O,'07_Campaign_Summary'!$A:$A,"CMP-004")
A20: Mofawtar - Retargeting - Demo Booking - Q2 | B20: =SUMIFS('07_Campaign_Summary'!$C:$C,'07_Campaign_Summary'!$A:$A,"CMP-005") | C20: =SUMIFS('07_Campaign_Summary'!$E:$E,'07_Campaign_Summary'!$A:$A,"CMP-005") | D20: =SUMIFS('07_Campaign_Summary'!$H:$H,'07_Campaign_Summary'!$A:$A,"CMP-005") | E20: =SUMIFS('07_Campaign_Summary'!$J:$J,'07_Campaign_Summary'!$A:$A,"CMP-005") | F20: =SUMIFS('07_Campaign_Summary'!$O:$O,'07_Campaign_Summary'!$A:$A,"CMP-005")

Sheet 00_ReadMe
A1: Mofawtar Meta Ads + CRM + ROAS Tracker | Q2 Sample Filled
A2: Invented Q2 data to understand the full flow: Meta Ads > Prospect Info > Lead > MQL / SQL / Deal > Cost > Revenue > ROAS.
A4: Purpose | B4: Pre-filled quarter of realistic dummy data so the team can understand the model before live CRM/Meta integration.
A5: Quarter | B5: 2026-04-01 to 2026-06-30
A6: Daily contacts | B6: Average ~30 prospects/day across WhatsApp, Messenger, Instagram DM, Website Form and Phone Call.
A7: Granularity | B7: Day, week, month, quarter + Campaign / Ad Set / Ad.
A8: Live usage | B8: Replace sample data in 02_Meta_Raw_Data and 03_Prospects_CRM with actual exports while keeping same headers.
A9: Matching key | B9: Campaign ID + Ad Set ID + Ad ID + Date.
A10: Note | B10: All numbers are invented sample data.

Sheet 01_Settings_Lists
A1: Settings, Lists & Definitions
A2: Lookup values and funnel definitions.
A4: Lifecycle Stages | B4: Lead Statuses | C4: Channels | D4: Owners | E4: Products | F4: Industries | G4: Lost Reasons | H4: Campaigns
A5: Lead | B5: New | C5: WhatsApp | D5: Ahmed | E5: Electronic Receipts | F5: Retail | G5: No budget | H5: In2out - MessCampaign#1 - Testing - 15/4
A6: MQL | B6: Contacted | C6: Messenger | D6: Mona | E6: Electronic Invoices | F6: Pharmacy | G6: Not decision maker | H6: In2out - MessCampaign#2 - Testing - 20/4
A7: SQL | B7: Qualified | C7: Instagram DM | D7: Kareem | E7: SaaS Subscription | F7: Restaurant | G7: Wrong fit | H7: Mofawtar - E-Receipt - Awareness - Q2
A8: Deal Won | B8: Proposal Sent | C8: Website Form | D8: Salma | E8: POS Integration | F8: Medical | G8: No response | H8: Mofawtar - Tax Invoice - Lead Gen - Q2
A9: Deal Lost | B9: Negotiation | C9: Phone Call | D9: Youssef | F9: Services | G9: Using competitor | H9: Mofawtar - Retargeting - Demo Booking - Q2
A10: Nurture | B10: Deal Won | F10: Distribution | G10: Price objection
B11: Deal Lost | F11: E-commerce
B12: Nurture | F12: Manufacturing

Sheet 02_Meta_Raw_Data
A1: 02 | Meta Ads Raw Data
A2: Daily/ad-level Meta data for full quarter.
A4: Date | B4: Campaign ID | C4: Campaign Name | D4: Ad Set ID | E4: Ad Set Name | F4: Ad ID | G4: Ad Name | H4: Objective | I4: Product | J4: Amount Spent | K4: Impressions | L4: Reach | M4: Link Clicks | N4: CPC | O4: CPM | P4: Messaging Conversations Started | Q4: WhatsApp Conversations | R4: Messenger Conversations | S4: Instagram DM Conversations | T4: Messaging Conversations Replied | U4: Meta Leads | V4: Website Registrations
A5: 46113 | B5: CMP-001 | C5: In2out - MessCampaign#1 - Testing - 15/4 | D5: AS-0101 | E5: In2out - MessCampaign#1 - Testing - 15/4 | Broad SMEs | F5: AD-010101 | G5: Pain Point Static | Broad SMEs | H5: Messages | I5: Electronic Receipts | J5: 263.21 | K5: 6783 | L5: 4234 | M5: 131 | N5: 2.01 | O5: 38.8 | P5: 37 | Q5: 22 | R5: 12 | S5: 3 | T5: 15 | U5: 0 | V5: 0
A6: 46113 | B6: CMP-001 | C6: In2out - MessCampaign#1 - Testing - 15/4 | D6: AS-0101 | E6: In2out - MessCampaign#1 - Testing - 15/4 | Broad SMEs | F6: AD-010102 | G6: Demo Reel | Broad SMEs | H6: Messages | I6: Electronic Receipts | J6: 166.01 | K6: 3064 | L6: 1707 | M6: 57 | N6: 2.91 | O6: 54.17 | P6: 15 | Q6: 8 | R6: 3 | S6: 4 | T6: 8 | U6: 0 | V6: 0
A7: 46113 | B7: CMP-001 | C7: In2out - MessCampaign#1 - Testing - 15/4 | D7: AS-0101 | E7: In2out - MessCampaign#1 - Testing - 15/4 | Broad SMEs | F7: AD-010103 | G7: Offer Carousel | Broad SMEs | H7: Messages | I7: Electronic Receipts | J7: 301.64 | K7: 4998 | L7: 3208 | M7: 88 | N7: 3.43 | O7: 60.34 | P7: 29 | Q7: 14 | R7: 7 | S7: 8 | T7: 12 | U7: 1 | V7: 0
A8: 46113 | B8: CMP-001 | C8: In2out - MessCampaign#1 - Testing - 15/4 | D8: AS-0102 | E8: In2out - MessCampaign#1 - Testing - 15/4 | Interest Tax Owners | F8: AD-010201 | G8: Pain Point Static | Interest Tax Owners | H8: Messages | I8: Electronic Receipts | J8: 301.95 | K8: 4921 | L8: 3419 | M8: 189 | N8: 1.6 | O8: 61.35 | P8: 39 | Q8: 22 | R8: 13 | S8: 4 | T8: 23 | U8: 1 | V8: 0
A9: 46113 | B9: CMP-001 | C9: In2out - MessCampaign#1 - Testing - 15/4 | D9: AS-0102 | E9: In2out - MessCampaign#1 - Testing - 15/4 | Interest Tax Owners | F9: AD-010202 | G9: Demo Reel | Interest Tax Owners | H9: Messages | I9: Electronic Receipts | J9: 278.26 | K9: 7050 | L9: 4311 | M9: 148 | N9: 1.88 | O9: 39.47 | P9: 22 | Q9: 10 | R9: 5 | S9: 7 | T9: 10 | U9: 0 | V9: 0
A10: 46113 | B10: CMP-002 | C10: In2out - MessCampaign#2 - Testing - 20/4 | D10: AS-0201 | E10: In2out - MessCampaign#2 - Testing - 20/4 | Broad SMEs | F10: AD-020101 | G10: Pain Point Static | Broad SMEs | H10: Messages | I10: Electronic Receipts | J10: 201.01 | K10: 4496 | L10: 2796 | M10: 146 | N10: 1.38 | O10: 44.7 | P10: 30 | Q10: 17 | R10: 6 | S10: 7 | T10: 17 | U10: 0 | V10: 0
A11: 46113 | B11: CMP-002 | C11: In2out - MessCampaign#2 - Testing - 20/4 | D11: AS-0201 | E11: In2out - MessCampaign#2 - Testing - 20/4 | Broad SMEs | F11: AD-020102 | G11: Demo Reel | Broad SMEs | H11: Messages | I11: Electronic Receipts | J11: 344.08 | K11: 5883 | L11: 4120 | M11: 159 | N11: 2.16 | O11: 58.48 | P11: 37 | Q11: 23 | R11: 7 | S11: 7 | T11: 13 | U11: 0 | V11: 0
A12: 46113 | B12: CMP-002 | C12: In2out - MessCampaign#2 - Testing - 20/4 | D12: AS-0201 | E12: In2out - MessCampaign#2 - Testing - 20/4 | Broad SMEs | F12: AD-020103 | G12: Offer Carousel | Broad SMEs | H12: Messages | I12: Electronic Receipts | J12: 164.24 | K12: 2409 | L12: 1894 | M12: 45 | N12: 3.65 | O12: 68.17 | P12: 9 | Q12: 4 | R12: 4 | S12: 1 | T12: 4 | U12: 0 | V12: 0
A13: 46113 | B13: CMP-002 | C13: In2out - MessCampaign#2 - Testing - 20/4 | D13: AS-0202 | E13: In2out - MessCampaign#2 - Testing - 20/4 | Interest Tax Owners | F13: AD-020201 | G13: Pain Point Static | Interest Tax Owners | H13: Messages | I13: Electronic Receipts | J13: 245.18 | K13: 5283 | L13: 3739 | M13: 167 | N13: 1.47 | O13: 46.41 | P13: 27 | Q13: 12 | R13: 12 | S13: 3 | T13: 13 | U13: 0 | V13: 0
A14: 46113 | B14: CMP-002 | C14: In2out - MessCampaign#2 - Testing - 20/4 | D14: AS-0202 | E14: In2out - MessCampaign#2 - Testing - 20/4 | Interest Tax Owners | F14: AD-020202 | G14: Demo Reel | Interest Tax Owners | H14: Messages | I14: Electronic Receipts | J14: 140.83 | K14: 2424 | L14: 1851 | M14: 51 | N14: 2.76 | O14: 58.08 | P14: 5 | Q14: 2 | R14: 2 | S14: 1 | T14: 2 | U14: 0 | V14: 0
A15: 46113 | B15: CMP-003 | C15: Mofawtar - E-Receipt - Awareness - Q2 | D15: AS-0301 | E15: Mofawtar - E-Receipt - Awareness - Q2 | Broad SMEs | F15: AD-030101 | G15: Pain Point Static | Broad SMEs | H15: Messages | I15: Electronic Receipts | J15: 118.15 | K15: 1934 | L15: 1419 | M15: 46 | N15: 2.57 | O15: 61.06 | P15: 7 | Q15: 4 | R15: 1 | S15: 2 | T15: 3 | U15: 0 | V15: 0
A16: 46113 | B16: CMP-003 | C16: Mofawtar - E-Receipt - Awareness - Q2 | D16: AS-0301 | E16: Mofawtar - E-Receipt - Awareness - Q2 | Broad SMEs | F16: AD-030102 | G16: Demo Reel | Broad SMEs | H16: Messages | I16: Electronic Receipts | J16: 317.82 | K16: 6845 | L16: 4689 | M16: 109 | N16: 2.92 | O16: 46.43 | P16: 28 | Q16: 18 | R16: 5 | S16: 5 | T16: 15 | U16: 0 | V16: 0
... A2643: 46203 | B2643: CMP-005 | C2643: Mofawtar - Retargeting - Demo Booking - Q2 | D2643: AS-0503 | E2643: Mofawtar - Retargeting - Demo Booking - Q2 | Retargeting Visitors | F2643: AD-050302 | G2643: Demo Reel | Retargeting Visitors | H2643: Conversions | I2643: SaaS Subscription | J2643: 247.03 | K2643: 4845 | L2643: 3555 | M2643: 121 | N2643: 2.04 | O2643: 50.98 | P2643: 30 | Q2643: 19 | R2643: 5 | S2643: 6 | T2643: 17 | U2643: 0 | V2643: 0

Sheet 03_Prospects_CRM
A1: 03 | Prospects CRM
A2: Contact-level CRM data: the source of truth for MQL/SQL/Deal/Revenue.
A4: Lead ID | B4: Created Date | C4: Contact Name | D4: Company | E4: Phone | F4: Email | G4: City | H4: Industry | I4: Product | J4: Lead Source | K4: Channel | L4: Campaign ID | M4: Campaign Name | N4: Ad Set ID | O4: Ad Set Name | P4: Ad ID | Q4: Ad Name | R4: Owner | S4: Lead Status | T4: Lifecycle Stage | U4: Lead Score | V4: Package | W4: Expected Deal Value | X4: Revenue | Y4: MQL Date | Z4: SQL Date | AA4: Deal Won Date | AB4: Lost Date | AC4: First Response Minutes | AD4: SLA Met | AE4: Lost Reason | AF4: Next Follow-up Date | AG4: Notes
A5: L-00001 | B5: 46113 | C5: Customer 0001 | D5: Smart Medical 715 | E5: 01163404755 | F5: lead0001@example.com | G5: Assiut | H5: Medical | I5: Electronic Receipts | J5: Meta Ads | K5: Phone Call | L5: CMP-003 | M5: Mofawtar - E-Receipt - Awareness - Q2 | N5: AS-0302 | O5: Mofawtar - E-Receipt - Awareness - Q2 | Interest Tax Owners | P5: AD-030202 | Q5: Demo Reel | Interest Tax Owners | R5: Mona | S5: Contacted | T5: Lead | U5: 35 | V5: Starter 850 | W5: 850 | X5: 0 | AC5: 464 | AD5: No | AF5: 46114 | AG5: Asked for demo
A6: L-00002 | B6: 46113 | C6: Customer 0002 | D6: Golden Manufacturing 554 | E6: 01277131360 | F6: lead0002@example.com | G6: Giza | H6: Manufacturing | I6: Electronic Receipts | J6: Meta Ads | K6: WhatsApp | L6: CMP-001 | M6: In2out - MessCampaign#1 - Testing - 15/4 | N6: AS-0101 | O6: In2out - MessCampaign#1 - Testing - 15/4 | Broad SMEs | P6: AD-010102 | Q6: Demo Reel | Broad SMEs | R6: Youssef | S6: Nurture | T6: Nurture | U6: 29 | V6: Starter 850 | W6: 850 | X6: 0 | AC6: 382 | AD6: No | AF6: 46117 | AG6: High intent
A7: L-00003 | B7: 46113 | C7: Customer 0003 | D7: Green E-commerce 142 | E7: 01219880297 | F7: lead0003@example.com | G7: Qena | H7: E-commerce | I7: Electronic Receipts | J7: Meta Ads | K7: WhatsApp | L7: CMP-001 | M7: In2out - MessCampaign#1 - Testing - 15/4 | N7: AS-0101 | O7: In2out - MessCampaign#1 - Testing - 15/4 | Broad SMEs | P7: AD-010101 | Q7: Pain Point Static | Broad SMEs | R7: Salma | S7: Contacted | T7: Lead | U7: 58 | V7: Enterprise 12000 | W7: 12000 | X7: 0 | AC7: 17 | AD7: Yes | AF7: 46114 | AG7: Follow-up via WhatsApp
A8: L-00004 | B8: 46113 | C8: Customer 0004 | D8: Blue Medical 212 | E8: 01588583215 | F8: lead0004@example.com | G8: Zagazig | H8: Medical | I8: Electronic Invoices | J8: Meta Ads | K8: WhatsApp | L8: CMP-004 | M8: Mofawtar - Tax Invoice - Lead Gen - Q2 | N8: AS-0402 | O8: Mofawtar - Tax Invoice - Lead Gen - Q2 | Interest Tax Owners | P8: AD-040202 | Q8: Demo Reel | Interest Tax Owners | R8: Mona | S8: Contacted | T8: Lead | U8: 44 | V8: Starter 850 | W8: 850 | X8: 0 | AC8: 334 | AD8: No | AF8: 46118 | AG8: High intent
A9: L-00005 | B9: 46113 | C9: Customer 0005 | D9: Nile Distribution 299 | E9: 01112603456 | F9: lead0005@example.com | G9: Ismailia | H9: Distribution | I9: SaaS Subscription | J9: Meta Ads | K9: Instagram DM | L9: CMP-005 | M9: Mofawtar - Retargeting - Demo Booking - Q2 | N9: AS-0503 | O9: Mofawtar - Retargeting - Demo Booking - Q2 | Retargeting Visitors | P9: AD-050301 | Q9: Pain Point Static | Retargeting Visitors | R9: Kareem | S9: Contacted | T9: Lead | U9: 34 | V9: Starter 850 | W9: 850 | X9: 0 | AC9: 230 | AD9: No | AF9: 46117 | AG9: Price sensitive
A10: L-00006 | B10: 46113 | C10: Customer 0006 | D10: Omega Services 143 | E10: 01290703795 | F10: lead0006@example.com | G10: Giza | H10: Services | I10: Electronic Receipts | J10: Meta Ads | K10: Website Form | L10: CMP-001 | M10: In2out - MessCampaign#1 - Testing - 15/4 | N10: AS-0101 | O10: In2out - MessCampaign#1 - Testing - 15/4 | Broad SMEs | P10: AD-010103 | Q10: Offer Carousel | Broad SMEs | R10: Mona | S10: Contacted | T10: Lead | U10: 53 | V10: Business 5000 | W10: 5000 | X10: 0 | AC10: 84 | AD10: No | AF10: 46118 | AG10: Needs tax setup
A11: L-00007 | B11: 46113 | C11: Customer 0007 | D11: Lotus Manufacturing 185 | E11: 01249871655 | F11: lead0007@example.com | G11: Mansoura | H11: Manufacturing | I11: Electronic Receipts | J11: Meta Ads | K11: Instagram DM | L11: CMP-001 | M11: In2out - MessCampaign#1 - Testing - 15/4 | N11: AS-0102 | O11: In2out - MessCampaign#1 - Testing - 15/4 | Interest Tax Owners | P11: AD-010201 | Q11: Pain Point Static | Interest Tax Owners | R11: Salma | S11: Contacted | T11: Lead | U11: 35 | V11: Growth 2400 | W11: 2400 | X11: 0 | AC11: 239 | AD11: No | AF11: 46115 | AG11: Imported from Meta conversation
A12: L-00008 | B12: 46113 | C12: Customer 0008 | D12: Smart Manufacturing 925 | E12: 01031030803 | F12: lead0008@example.com | G12: Qena | H12: Manufacturing | I12: Electronic Receipts | J12: Referral | K12: Website Form | L12: CMP-002 | M12: In2out - MessCampaign#2 - Testing - 20/4 | N12: AS-0201 | O12: In2out - MessCampaign#2 - Testing - 20/4 | Broad SMEs | P12: AD-020103 | Q12: Offer Carousel | Broad SMEs | R12: Mona | S12: Qualified | T12: MQL | U12: 70 | V12: Starter 850 | W12: 850 | X12: 0 | Y12: 46115 | AC12: 388 | AD12: No | AF12: 46115 | AG12: Price sensitive
A13: L-00009 | B13: 46113 | C13: Customer 0009 | D13: Omega E-commerce 725 | E13: 01274817663 | F13: lead0009@example.com | G13: Mansoura | H13: E-commerce | I13: Electronic Receipts | J13: Meta Ads | K13: WhatsApp | L13: CMP-002 | M13: In2out - MessCampaign#2 - Testing - 20/4 | N13: AS-0201 | O13: In2out - MessCampaign#2 - Testing - 20/4 | Broad SMEs | P13: AD-020103 | Q13: Offer Carousel | Broad SMEs | R13: Ahmed | S13: Contacted | T13: Lead | U13: 21 | V13: Growth 2400 | W13: 2400 | X13: 0 | AC13: 36 | AD13: Yes | AF13: 46115 | AG13: Price sensitive
A14: L-00010 | B14: 46113 | C14: Customer 0010 | D14: Delta Restaurant 619 | E14: 01046028074 | F14: lead0010@example.com | G14: Cairo | H14: Restaurant | I14: Electronic Receipts | J14: Website | K14: Website Form | L14: CMP-002 | M14: In2out - MessCampaign#2 - Testing - 20/4 | N14: AS-0202 | O14: In2out - MessCampaign#2 - Testing - 20/4 | Interest Tax Owners | P14: AD-020202 | Q14: Demo Reel | Interest Tax Owners | R14: Mona | S14: Contacted | T14: Lead | U14: 59 | V14: Starter 850 | W14: 850 | X14: 0 | AC14: 121 | AD14: No | AF14: 46115 | AG14: Asked for demo
A15: L-00011 | B15: 46113 | C15: Customer 0011 | D15: Alfa Manufacturing 441 | E15: 01011546923 | F15: lead0011@example.com | G15: Giza | H15: Manufacturing | I15: SaaS Subscription | J15: Meta Ads | K15: WhatsApp | L15: CMP-005 | M15: Mofawtar - Retargeting - Demo Booking - Q2 | N15: AS-0503 | O15: Mofawtar - Retargeting - Demo Booking - Q2 | Retargeting Visitors | P15: AD-050301 | Q15: Pain Point Static | Retargeting Visitors | R15: Mona | S15: Contacted | T15: Lead | U15: 43 | V15: Starter 850 | W15: 850 | X15: 0 | AC15: 446 | AD15: No | AF15: 46115 | AG15: Follow-up via WhatsApp
A16: L-00012 | B16: 46113 | C16: Customer 0012 | D16: Target Services 672 | E16: 01292739430 | F16: lead0012@example.com | G16: Suez | H16: Services | I16: SaaS Subscription | J16: Meta Ads | K16: Messenger | L16: CMP-005 | M16: Mofawtar - Retargeting - Demo Booking - Q2 | N16: AS-0503 | O16: Mofawtar - Retargeting - Demo Booking - Q2 | Retargeting Visitors | P16: AD-050302 | Q16: Demo Reel | Retargeting Visitors | R16: Salma | S16: Nurture | T16: Nurture | U16: 47 | V16: Growth 2400 | W16: 2400 | X16: 0 | AC16: 409 | AD16: No | AF16: 46119 | AG16: Asked for demo
A17: L-00013 | B17: 46113 | C17: Customer 0013 | D17: Fast Medical 808 | E17: 01164047337 | F17: lead0013@example.com | G17: Zagazig | H17: Medical | I17: SaaS Subscription | J17: Meta Ads | K17: Phone Call | L17: CMP-005 | M17: Mofawtar - Retargeting - Demo Booking - Q2 | N17: AS-0502 | O17: Mofawtar - Retargeting - Demo Booking - Q2 | Interest Tax Owners | P17: AD-050202 | Q17: Demo Reel | Interest Tax Owners | R17: Youssef | S17: Contacted | T17: Lead | U17: 37 | V17: Business 5000 | W17: 5000 | X17: 0 | AC17: 241 | AD17: No | AF17: 46119 | AG17: Needs tax setup
A18: L-00014 | B18: 46113 | C18: Customer 0014 | D18: Royal Retail 510 | E18: 01153605467 | F18: lead0014@example.com | G18: Zagazig | H18: Retail | I18: Electronic Invoices | J18: Meta Ads | K18: Messenger | L18: CMP-004 | M18: Mofawtar - Tax Invoice - Lead Gen - Q2 | N18: AS-0401 | O18: Mofawtar - Tax Invoice - Lead Gen - Q2 | Broad SMEs | P18: AD-040101 | Q18: Pain Point Static | Broad SMEs | R18: Salma | S18: Qualified | T18: MQL | U18: 62 | V18: Business 5000 | W18: 5000 | X18: 0 | Y18: 46116 | AC18: 77 | AD18: No | AF18: 46114 | AG18: Imported from Meta conversation
A19: L-00015 | B19: 46113 | C19: Customer 0015 | D19: Smart Restaurant 646 | E19: 01151040696 | F19: lead0015@example.com | G19: Mansoura | H19: Restaurant | I19: Electronic Receipts | J19: Meta Ads | K19: Messenger | L19: CMP-003 | M19: Mofawtar - E-Receipt - Awareness - Q2 | N19: AS-0301 | O19: Mofawtar - E-Receipt - Awareness - Q2 | Broad SMEs | P19: AD-030101 | Q19: Pain Point Static | Broad SMEs | R19: Ahmed | S19: Contacted | T19: Lead | U19: 58 | V19: Business 5000 | W19: 5000 | X19: 0 | AC19: 295 | AD19: No | AF19: 46117 | AG19: Follow-up via WhatsApp
A20: L-00016 | B20: 46113 | C20: Customer 0016 | D20: Smart Restaurant 857 | E20: 01039704405 | F20: lead0016@example.com | G20: Mansoura | H20: Restaurant | I20: Electronic Receipts | J20: Meta Ads | K20: WhatsApp | L20: CMP-002 | M20: In2out - MessCampaign#2 - Testing - 20/4 | N20: AS-0201 | O20: In2out - MessCampaign#2 - Testing - 20/4 | Broad SMEs | P20: AD-020103 | Q20: Offer Carousel | Broad SMEs | R20: Kareem | S20: Contacted | T20: Lead | U20: 43 | V20: Growth 2400 | W20: 2400 | X20: 0 | AC20: 104 | AD20: No | AF20: 46117 | AG20: Needs tax setup
A21: L-00017 | B21: 46113 | C21: Customer 0017 | D21: Target Medical 497 | E21: 01212904310 | F21: lead0017@example.com | G21: Qena | H21: Medical | I21: Electronic Receipts | J21: Meta Ads | K21: Website Form | L21: CMP-002 | M21: In2out - MessCampaign#2 - Testing - 20/4 | N21: AS-0201 | O21: In2out - MessCampaign#2 - Testing - 20/4 | Broad SMEs | P21: AD-020101 | Q21: Pain Point Static | Broad SMEs | R21: Ahmed | S21: Contacted | T21: Lead | U21: 40 | V21: Starter 850 | W21: 850 | X21: 0 | AC21: 153 | AD21: No | AF21: 46115 | AG21: Imported from Meta conversation
A22: L-00018 | B22: 46113 | C22: Customer 0018 | D22: Lotus Retail 735 | E22: 01059075036 | F22: lead0018@example.com | G22: Zagazig | H22: Retail | I22: Electronic Receipts | J22: Meta Ads | K22: WhatsApp | L22: CMP-001 | M22: In2out - MessCampaign#1 - Testing - 15/4 | N22: AS-0101 | O22: In2out - MessCampaign#1 - Testing - 15/4 | Broad SMEs | P22: AD-010102 | Q22: Demo Reel | Broad SMEs | R22: Kareem | S22: Deal Lost | T22: Deal Lost | U22: 34 | V22: Starter 850 | W22: 850 | X22: 0 | AB22: 46115 | AC22: 52 | AD22: Yes | AE22: No response | AG22: High intent
A23: L-00019 | B23: 46113 | C23: Customer 0019 | D23: Cairo Distribution 338 | E23: 01178543887 | F23: lead0019@example.com | G23: Cairo | H23: Distribution | I23: SaaS Subscription | J23: Referral | K23: Instagram DM | L23: CMP-005 | M23: Mofawtar - Retargeting - Demo Booking - Q2 | N23: AS-0501 | O23: Mofawtar - Retargeting - Demo Booking - Q2 | Broad SMEs | P23: AD-050101 | Q23: Pain Point Static | Broad SMEs | R23: Salma | S23: Deal Lost | T23: Deal Lost | U23: 46 | V23: Growth 2400 | W23: 2400 | X23: 0 | AB23: 46117 | AC23: 193 | AD23: No | AE23: Using competitor | AG23: High intent
A24: L-00020 | B24: 46113 | C24: Customer 0020 | D24: Nile Services 925 | E24: 01568014632 | F24: lead0020@example.com | G24: Mansoura | H24: Services | I24: Electronic Invoices | J24: Meta Ads | K24: Messenger | L24: CMP-004 | M24: Mofawtar - Tax Invoice - Lead Gen - Q2 | N24: AS-0402 | O24: Mofawtar - Tax Invoice - Lead Gen - Q2 | Interest Tax Owners | P24: AD-040201 | Q24: Pain Point Static | Interest Tax Owners | R24: Ahmed | S24: Qualified | T24: MQL | U24: 57 | V24: Starter 850 | W24: 850 | X24: 0 | Y24: 46116 | AC24: 186 | AD24: No | AF24: 46118 | AG24: Imported from Meta conversation
A25: L-00021 | B25: 46113 | C25: Customer 0021 | D25: Golden E-commerce 383 | E25: 01541869535 | F25: lead0021@example.com | G25: Zagazig | H25: E-commerce | I25: Electronic Receipts | J25: Meta Ads | K25: Website Form | L25: CMP-002 | M25: In2out - MessCampaign#2 - Testing - 20/4 | N25: AS-0201 | O25: In2out - MessCampaign#2 - Testing - 20/4 | Broad SMEs | P25: AD-020101 | Q25: Pain Point Static | Broad SMEs | R25: Ahmed | S25: Contacted | T25: Lead | U25: 54 | V25: Starter 850 | W25: 850 | X25: 0 | AC25: 277 | AD25: No | AF25: 46114 | AG25: Asked for demo
A26: L-00022 | B26: 46113 | C26: Customer 0022 | D26: Omega Retail 619 | E26: 01571817885 | F26: lead0022@example.com | G26: Giza | H26: Retail | I26: Electronic Receipts | J26: Meta Ads | K26: WhatsApp | L26: CMP-002 | M26: In2out - MessCampaign#2 - Testing - 20/4 | N26: AS-0201 | O26: In2out - MessCampaign#2 - Testing - 20/4 | Broad SMEs | P26: AD-020103 | Q26: Offer Carousel | Broad SMEs | R26: Kareem | S26: Contacted | T26: Lead | U26: 70 | V26: Starter 850 | W26: 850 | X26: 0 | AC26: 336 | AD26: No | AF26: 46119 | AG26: Needs tax setup
A27: L-00023 | B27: 46113 | C27: Customer 0023 | D27: Blue Retail 61 | E27: 01190516640 | F27: lead0023@example.com | G27: Alexandria | H27: Retail | I27: Electronic Receipts | J27: Meta Ads | K27: Phone Call | L27: CMP-001 | M27: In2out - MessCampaign#1 - Testing - 15/4 | N27: AS-0101 | O27: In2out - MessCampaign#1 - Testing - 15/4 | Broad SMEs | P27: AD-010101 | Q27: Pain Point Static | Broad SMEs | R27: Youssef | S27: Deal Lost | T27: Deal Lost | U27: 33 | V27: Starter 850 | W27: 850 | X27: 0 | AB27: 46118 | AC27: 378 | AD27: No | AE27: Using competitor | AG27: Follow-up via WhatsApp
A28: L-00024 | B28: 46113 | C28: Customer 0024 | D28: Fast E-commerce 558 | E28: 01221891017 | F28: lead0024@example.com | G28: Assiut | H28: E-commerce | I28: Electronic Receipts | J28: Meta Ads | K28: Phone Call | L28: CMP-002 | M28: In2out - MessCampaign#2 - Testing - 20/4 | N28: AS-0201 | O28: In2out - MessCampaign#2 - Testing - 20/4 | Broad SMEs | P28: AD-020102 | Q28: Demo Reel | Broad SMEs | R28: Ahmed | S28: Contacted | T28: Lead | U28: 53 | V28: Starter 850 | W28: 850 | X28: 0 | AC28: 1449 | AD28: No | AF28: 46116 | AG28: Asked for demo
A29: L-00025 | B29: 46113 | C29: Customer 0025 | D29: Delta E-commerce 500 | E29: 01175535180 | F29: lead0025@example.com | G29: Alexandria | H29: E-commerce | I29: SaaS Subscription | J29: Meta Ads | K29: Instagram DM | L29: CMP-005 | M29: Mofawtar - Retargeting - Demo Booking - Q2 | N29: AS-0503 | O29: Mofawtar - Retargeting - Demo Booking - Q2 | Retargeting Visitors | P29: AD-050302 | Q29: Demo Reel | Retargeting Visitors | R29: Kareem | S29: Qualified | T29: MQL | U29: 63 | V29: Growth 2400 | W29: 2400 | X29: 0 | Y29: 46113 | AC29: 93 | AD29: No | AF29: 46119 | AG29: Imported from Meta conversation
A30: L-00026 | B30: 46113 | C30: Customer 0026 | D30: Fast Medical 809 | E30: 01081600765 | F30: lead0026@example.com | G30: Mansoura | H30: Medical | I30: Electronic Receipts | J30: Meta Ads | K30: WhatsApp | L30: CMP-001 | M30: In2out - MessCampaign#1 - Testing - 15/4 | N30: AS-0102 | O30: In2out - MessCampaign#1 - Testing - 15/4 | Interest Tax Owners | P30: AD-010201 | Q30: Pain Point Static | Interest Tax Owners | R30: Kareem | S30: Contacted | T30: Lead | U30: 46 | V30: Starter 850 | W30: 850 | X30: 0 | AC30: 373 | AD30: No | AF30: 46117 | AG30: Follow-up via WhatsApp
A31: L-00027 | B31: 46113 | C31: Customer 0027 | D31: Lotus Distribution 923 | E31: 01044925104 | F31: lead0027@example.com | G31: Suez | H31: Distribution | I31: Electronic Receipts | J31: Meta Ads | K31: Messenger | L31: CMP-003 | M31: Mofawtar - E-Receipt - Awareness - Q2 | N31: AS-0302 | O31: Mofawtar - E-Receipt - Awareness - Q2 | Interest Tax Owners | P31: AD-030201 | Q31: Pain Point Static | Interest Tax Owners | R31: Ahmed | S31: Contacted | T31: Lead | U31: 36 | V31: Starter 850 | W31: 850 | X31: 0 | AC31: 213 | AD31: No | AF31: 46118 | AG31: High intent
A32: L-00028 | B32: 46113 | C32: Customer 0028 | D32: Nile Manufacturing 445 | E32: 01257556484 | F32: lead0028@example.com | G32: Suez | H32: Manufacturing | I32: Electronic Receipts | J32: Meta Ads | K32: Instagram DM | L32: CMP-003 | M32: Mofawtar - E-Receipt - Awareness - Q2 | N32: AS-0302 | O32: Mofawtar - E-Receipt - Awareness - Q2 | Interest Tax Owners | P32: AD-030202 | Q32: Demo Reel | Interest Tax Owners | R32: Kareem | S32: Contacted | T32: Lead | U32: 24 | V32: Starter 850 | W32: 850 | X32: 0 | AC32: 54 | AD32: Yes | AF32: 46119 | AG32: Follow-up via WhatsApp
A33: L-00029 | B33: 46113 | C33: Customer 0029 | D33: Cairo Medical 26 | E33: 01028079492 | F33: lead0029@example.com | G33: Zagazig | H33: Medical | I33: Electronic Receipts | J33: Meta Ads | K33: Phone Call | L33: CMP-003 | M33: Mofawtar - E-Receipt - Awareness - Q2 | N33: AS-0301 | O33: Mofawtar - E-Receipt - Awareness - Q2 | Broad SMEs | P33: AD-030101 | Q33: Pain Point Static | Broad SMEs | R33: Ahmed | S33: Contacted | T33: Lead | U33: 58 | V33: Growth 2400 | W33: 2400 | X33: 0 | AC33: 480 | AD33: No | AF33: 46116 | AG33: Asked for demo
A34: L-00030 | B34: 46113 | C34: Customer 0030 | D34: Green Manufacturing 811 | E34: 01165792084 | F34: lead0030@example.com | G34: Giza | H34: Manufacturing | I34: Electronic Invoices | J34: Meta Ads | K34: WhatsApp | L34: CMP-004 | M34: Mofawtar - Tax Invoice - Lead Gen - Q2 | N34: AS-0403 | O34: Mofawtar - Tax Invoice - Lead Gen - Q2 | Retargeting Visitors | P34: AD-040302 | Q34: Demo Reel | Retargeting Visitors | R34: Salma | S34: Proposal Sent | T34: SQL | U34: 68 | V34: Growth 2400 | W34: 2400 | X34: 0 | Y34: 46116 | Z34: 46114 | AC34: 256 | AD34: No | AF34: 46118 | AG34: Asked for demo
A35: L-00031 | B35: 46114 | C35: Customer 0031 | D35: Royal Services 772 | E35: 01099363234 | F35: lead0031@example.com | G35: Qena | H35: Services | I35: Electronic Receipts | J35: Meta Ads | K35: Phone Call | L35: CMP-001 | M35: In2out - MessCampaign#1 - Testing - 15/4 | N35: AS-0101 | O35: In2out - MessCampaign#1 - Testing - 15/4 | Broad SMEs | P35: AD-010102 | Q35: Demo Reel | Broad SMEs | R35: Kareem | S35: Contacted | T35: Lead | U35: 46 | V35: Enterprise 12000 | W35: 12000 | X35: 0 | AC35: 19 | AD35: Yes | AF35: 46119 | AG35: Needs tax setup
A36: L-00032 | B36: 46114 | C36: Customer 0032 | D36: Smart Medical 827 | E36: 01243384061 | F36: lead0032@example.com | G36: Assiut | H36: Medical | I36: Electronic Receipts | J36: Meta Ads | K36: Instagram DM | L36: CMP-003 | M36: Mofawtar - E-Receipt - Awareness - Q2 | N36: AS-0302 | O36: Mofawtar - E-Receipt - Awareness - Q2 | Interest Tax Owners | P36: AD-030201 | Q36: Pain Point Static | Interest Tax Owners | R36: Youssef | S36: Qualified | T36: MQL | U36: 52 | V36: Starter 850 | W36: 850 | X36: 0 | Y36: 46114 | AC36: 112 | AD36: No | AF36: 46120 | AG36: High intent
A37: L-00033 | B37: 46114 | C37: Customer 0033 | D37: Nile Services 458 | E37: 01552156701 | F37: lead0033@example.com | G37: Tanta | H37: Services | I37: Electronic Receipts | J37: Meta Ads | K37: WhatsApp | L37: CMP-001 | M37: In2out - MessCampaign#1 - Testing - 15/4 | N37: AS-0102 | O37: In2out - MessCampaign#1 - Testing - 15/4 | Interest Tax Owners | P37: AD-010202 | Q37: Demo Reel | Interest Tax Owners | R37: Youssef | S37: Contacted | T37: Lead | U37: 34 | V37: Starter 850 | W37: 850 | X37: 0 | AC37: 1050 | AD37: No | AF37: 46118 | AG37: Needs tax setup
A38: L-00034 | B38: 46114 | C38: Customer 0034 | D38: Delta Pharmacy 179 | E38: 01143529159 | F38: lead0034@example.com | G38: Cairo | H38: Pharmacy | I38: Electronic Receipts | J38: Meta Ads | K38: WhatsApp | L38: CMP-003 | M38: Mofawtar - E-Receipt - Awareness - Q2 | N38: AS-0302 | O38: Mofawtar - E-Receipt - Awareness - Q2 | Interest Tax Owners | P38: AD-030201 | Q38: Pain Point Static | Interest Tax Owners | R38: Youssef | S38: Proposal Sent | T38: SQL | U38: 68 | V38: Starter 850 | W38: 850 | X38: 0 | Y38: 46117 | Z38: 46115 | AC38: 170 | AD38: No | AF38: 46117 | AG38: High intent
A39: L-00035 | B39: 46114 | C39: Customer 0035 | D39: Trust Retail 22 | E39: 01219321385 | F39: lead0035@example.com | G39: Suez | H39: Retail | I39: Electronic Receipts | J39: Meta Ads | K39: Instagram DM | L39: CMP-002 | M39: In2out - MessCampaign#2 - Testing - 20/4 | N39: AS-0202 | O39: In2out - MessCampaign#2 - Testing - 20/4 | Interest Tax Owners | P39: AD-020202 | Q39: Demo Reel | Interest Tax Owners | R39: Kareem | S39: Contacted | T39: Lead | U39: 38 | V39: Starter 850 | W39: 850 | X39: 0 | AC39: 454 | AD39: No | AF39: 46115 | AG39: Imported from Meta conversation
A40: L-00036 | B40: 46114 | C40: Customer 0036 | D40: Smart Restaurant 436 | E40: 01053806657 | F40: lead0036@example.com | G40: Alexandria | H40: Restaurant | I40: Electronic Receipts | J40: Meta Ads | K40: WhatsApp | L40: CMP-001 | M40: In2out - MessCampaign#1 - Testing - 15/4 | N40: AS-0101 | O40: In2out - MessCampaign#1 - Testing - 15/4 | Broad SMEs | P40: AD-010103 | Q40: Offer Carousel | Broad SMEs | R40: Salma | S40: Proposal Sent | T40: SQL | U40: 65 | V40: Starter 850 | W40: 850 | X40: 0 | Y40: 46117 | Z40: 46121 | AC40: 20 | AD40: Yes | AF40: 46119 | AG40: Price sensitive
A41: L-00037 | B41: 46114 | C41: Customer 0037 | D41: Smart Services 899 | E41: 01541501634 | F41: lead0037@example.com | G41: Ismailia | H41: Services | I41: Electronic Receipts | J41: Meta Ads | K41: Website Form | L41: CMP-001 | M41: In2out - MessCampaign#1 - Testing - 15/4 | N41: AS-0102 | O41: In2out - MessCampaign#1 - Testing - 15/4 | Interest Tax Owners | P41: AD-010201 | Q41: Pain Point Static | Interest Tax Owners | R41: Youssef | S41: Contacted | T41: Lead | U41: 39 | V41: Business 5000 | W41: 5000 | X41: 0 | AC41: 39 | AD41: Yes | AF41: 46117 | AG41: High intent
...

Sheet 04_Activity_Log
A1: 04 | Activity Log
A2: All daily events: lead created, first reply, MQL, demo/quote, payment.
A4: Event Date | B4: Event Timestamp | C4: Lead ID | D4: Event Type | E4: Channel | F4: Owner | G4: Campaign Name | H4: Ad Set Name | I4: Ad Name | J4: Event Notes | K4: Outcome
A5: 46113 | B5: 46113.41 | C5: L-00001 | D5: Lead Created | E5: Phone Call | F5: Mona | G5: Mofawtar - E-Receipt - Awareness - Q2 | H5: Mofawtar - E-Receipt - Awareness - Q2 | Interest Tax Owners | I5: Demo Reel | Interest Tax Owners | J5: Inbound prospect created | K5: Completed
A6: 46113 | B6: 46113.732 | C6: L-00001 | D6: First Reply | E6: Phone Call | F6: Mona | G6: Mofawtar - E-Receipt - Awareness - Q2 | H6: Mofawtar - E-Receipt - Awareness - Q2 | Interest Tax Owners | I6: Demo Reel | Interest Tax Owners | J6: Sales agent replied | K6: Completed
A7: 46113 | B7: 46113.433 | C7: L-00002 | D7: Lead Created | E7: WhatsApp | F7: Youssef | G7: In2out - MessCampaign#1 - Testing - 15/4 | H7: In2out - MessCampaign#1 - Testing - 15/4 | Broad SMEs | I7: Demo Reel | Broad SMEs | J7: Inbound prospect created | K7: Completed
A8: 46113 | B8: 46113.698 | C8: L-00002 | D8: First Reply | E8: WhatsApp | F8: Youssef | G8: In2out - MessCampaign#1 - Testing - 15/4 | H8: In2out - MessCampaign#1 - Testing - 15/4 | Broad SMEs | I8: Demo Reel | Broad SMEs | J8: Sales agent replied | K8: Completed
A9: 46113 | B9: 46113.483 | C9: L-00003 | D9: Lead Created | E9: WhatsApp | F9: Salma | G9: In2out - MessCampaign#1 - Testing - 15/4 | H9: In2out - MessCampaign#1 - Testing - 15/4 | Broad SMEs | I9: Pain Point Static | Broad SMEs | J9: Inbound prospect created | K9: Completed
A10: 46113 | B10: 46113.494 | C10: L-00003 | D10: First Reply | E10: WhatsApp | F10: Salma | G10: In2out - MessCampaign#1 - Testing - 15/4 | H10: In2out - MessCampaign#1 - Testing - 15/4 | Broad SMEs | I10: Pain Point Static | Broad SMEs | J10: Sales agent replied | K10: Completed
A11: 46113 | B11: 46113.607 | C11: L-00004 | D11: Lead Created | E11: WhatsApp | F11: Mona | G11: Mofawtar - Tax Invoice - Lead Gen - Q2 | H11: Mofawtar - Tax Invoice - Lead Gen - Q2 | Interest Tax Owners | I11: Demo Reel | Interest Tax Owners | J11: Inbound prospect created | K11: Completed
A12: 46113 | B12: 46113.839 | C12: L-00004 | D12: First Reply | E12: WhatsApp | F12: Mona | G12: Mofawtar - Tax Invoice - Lead Gen - Q2 | H12: Mofawtar - Tax Invoice - Lead Gen - Q2 | Interest Tax Owners | I12: Demo Reel | Interest Tax Owners | J12: Sales agent replied | K12: Completed
A13: 46113 | B13: 46113.871 | C13: L-00005 | D13: Lead Created | E13: Instagram DM | F13: Kareem | G13: Mofawtar - Retargeting - Demo Booking - Q2 | H13: Mofawtar - Retargeting - Demo Booking - Q2 | Retargeting Visitors | I13: Pain Point Static | Retargeting Visitors | J13: Inbound prospect created | K13: Completed
A14: 46114 | B14: 46114.031 | C14: L-00005 | D14: First Reply | E14: Instagram DM | F14: Kareem | G14: Mofawtar - Retargeting - Demo Booking - Q2 | H14: Mofawtar - Retargeting - Demo Booking - Q2 | Retargeting Visitors | I14: Pain Point Static | Retargeting Visitors | J14: Sales agent replied | K14: Completed
A15: 46113 | B15: 46113.836 | C15: L-00006 | D15: Lead Created | E15: Website Form | F15: Mona | G15: In2out - MessCampaign#1 - Testing - 15/4 | H15: In2out - MessCampaign#1 - Testing - 15/4 | Broad SMEs | I15: Offer Carousel | Broad SMEs | J15: Inbound prospect created | K15: Completed
A16: 46113 | B16: 46113.894 | C16: L-00006 | D16: First Reply | E16: Website Form | F16: Mona | G16: In2out - MessCampaign#1 - Testing - 15/4 | H16: In2out - MessCampaign#1 - Testing - 15/4 | Broad SMEs | I16: Offer Carousel | Broad SMEs | J16: Sales agent replied | K16: Completed
... A6545: 46208 | B6545: 46208.041 | C6545: L-02598 | D6545: Demo Booked | E6545: WhatsApp | F6545: Ahmed | G6545: In2out - MessCampaign#2 - Testing - 20/4 | H6545: In2out - MessCampaign#2 - Testing - 20/4 | Broad SMEs | I6545: Pain Point Static | Broad SMEs | J6545: Sales opportunity created | K6545: Completed

Sheet 05_Daily_Funnel
A1: 05 | Daily Funnel
A2: Daily operational KPIs for every day in the quarter.
A4: Date | B4: Day | C4: Spend | D4: Conversations | E4: CRM Leads | F4: MQL | G4: SQL | H4: Deals Won | I4: Deals Lost | J4: Revenue | K4: CPL | L4: Cost/MQL | M4: Cost/SQL | N4: CAC | O4: ROAS | P4: Reply Rate | Q4: SLA Met %
A5: 46113 | B5: Wed | C5: =SUMIFS('02_Meta_Raw_Data'!$J:$J,'02_Meta_Raw_Data'!$A:$A,$A5) | D5: =SUMIFS('02_Meta_Raw_Data'!$P:$P,'02_Meta_Raw_Data'!$A:$A,$A5) | E5: =COUNTIFS('03_Prospects_CRM'!$B:$B,$A5) | F5: =COUNTIFS('03_Prospects_CRM'!$B:$B,$A5,'03_Prospects_CRM'!$T:$T,"MQL")+COUNTIFS('03_Prospects_CRM'!$B:$B,$A5,'03_Prospects_CRM'!$T:$T,"SQL")+COUNTIFS('03_Prospects_CRM'!$B:$B,$A5,'03_Prospects_CRM'!$T:$T,"Deal Won") | G5: =COUNTIFS('03_Prospects_CRM'!$B:$B,$A5,'03_Prospects_CRM'!$T:$T,"SQL")+COUNTIFS('03_Prospects_CRM'!$B:$B,$A5,'03_Prospects_CRM'!$T:$T,"Deal Won") | H5: =COUNTIFS('03_Prospects_CRM'!$B:$B,$A5,'03_Prospects_CRM'!$T:$T,"Deal Won") | I5: =COUNTIFS('03_Prospects_CRM'!$B:$B,$A5,'03_Prospects_CRM'!$T:$T,"Deal Lost") | J5: =SUMIFS('03_Prospects_CRM'!$X:$X,'03_Prospects_CRM'!$B:$B,$A5) | K5: =IFERROR(C5/E5,0) | L5: =IFERROR(C5/F5,0) | M5: =IFERROR(C5/G5,0) | N5: =IFERROR(C5/H5,0) | O5: =IFERROR(J5/C5,0) | P5: =IFERROR(SUMIFS('02_Meta_Raw_Data'!$T:$T,'02_Meta_Raw_Data'!$A:$A,$A5)/D5,0) | Q5: =IFERROR(COUNTIFS('03_Prospects_CRM'!$B:$B,$A5,'03_Prospects_CRM'!$AD:$AD,"Yes")/E5,0)
A6: 46114 | B6: Thu | C6: =SUMIFS('02_Meta_Raw_Data'!$J:$J,'02_Meta_Raw_Data'!$A:$A,$A6) | D6: =SUMIFS('02_Meta_Raw_Data'!$P:$P,'02_Meta_Raw_Data'!$A:$A,$A6) | E6: =COUNTIFS('03_Prospects_CRM'!$B:$B,$A6) | F6: =COUNTIFS('03_Prospects_CRM'!$B:$B,$A6,'03_Prospects_CRM'!$T:$T,"MQL")+COUNTIFS('03_Prospects_CRM'!$B:$B,$A6,'03_Prospects_CRM'!$T:$T,"SQL")+COUNTIFS('03_Prospects_CRM'!$B:$B,$A6,'03_Prospects_CRM'!$T:$T,"Deal Won") | G6: =COUNTIFS('03_Prospects_CRM'!$B:$B,$A6,'03_Prospects_CRM'!$T:$T,"SQL")+COUNTIFS('03_Prospects_CRM'!$B:$B,$A6,'03_Prospects_CRM'!$T:$T,"Deal Won") | H6: =COUNTIFS('03_Prospects_CRM'!$B:$B,$A6,'03_Prospects_CRM'!$T:$T,"Deal Won") | I6: =COUNTIFS('03_Prospects_CRM'!$B:$B,$A6,'03_Prospects_CRM'!$T:$T,"Deal Lost") | J6: =SUMIFS('03_Prospects_CRM'!$X:$X,'03_Prospects_CRM'!$B:$B,$A6) | K6: =IFERROR(C6/E6,0) | L6: =IFERROR(C6/F6,0) | M6: =IFERROR(C6/G6,0) | N6: =IFERROR(C6/H6,0) | O6: =IFERROR(J6/C6,0) | P6: =IFERROR(SUMIFS('02_Meta_Raw_Data'!$T:$T,'02_Meta_Raw_Data'!$A:$A,$A6)/D6,0) | Q6: =IFERROR(COUNTIFS('03_Prospects_CRM'!$B:$B,$A6,'03_Prospects_CRM'!$AD:$AD,"Yes")/E6,0)
A7: 46115 | B7: Fri | C7: =SUMIFS('02_Meta_Raw_Data'!$J:$J,'02_Meta_Raw_Data'!$A:$A,$A7) | D7: =SUMIFS('02_Meta_Raw_Data'!$P:$P,'02_Meta_Raw_Data'!$A:$A,$A7) | E7: =COUNTIFS('03_Prospects_CRM'!$B:$B,$A7) | F7: =COUNTIFS('03_Prospects_CRM'!$B:$B,$A7,'03_Prospects_CRM'!$T:$T,"MQL")+COUNTIFS('03_Prospects_CRM'!$B:$B,$A7,'03_Prospects_CRM'!$T:$T,"SQL")+COUNTIFS('03_Prospects_CRM'!$B:$B,$A7,'03_Prospects_CRM'!$T:$T,"Deal Won") | G7: =COUNTIFS('03_Prospects_CRM'!$B:$B,$A7,'03_Prospects_CRM'!$T:$T,"SQL")+COUNTIFS('03_Prospects_CRM'!$B:$B,$A7,'03_Prospects_CRM'!$T:$T,"Deal Won") | H7: =COUNTIFS('03_Prospects_CRM'!$B:$B,$A7,'03_Prospects_CRM'!$T:$T,"Deal Won") | I7: =COUNTIFS('03_Prospects_CRM'!$B:$B,$A7,'03_Prospects_CRM'!$T:$T,"Deal Lost") | J7: =SUMIFS('03_Prospects_CRM'!$X:$X,'03_Prospects_CRM'!$B:$B,$A7) | K7: =IFERROR(C7/E7,0) | L7: =IFERROR(C7/F7,0) | M7: =IFERROR(C7/G7,0) | N7: =IFERROR(C7/H7,0) | O7: =IFERROR(J7/C7,0) | P7: =IFERROR(SUMIFS('02_Meta_Raw_Data'!$T:$T,'02_Meta_Raw_Data'!$A:$A,$A7)/D7,0) | Q7: =IFERROR(COUNTIFS('03_Prospects_CRM'!$B:$B,$A7,'03_Prospects_CRM'!$AD:$AD,"Yes")/E7,0)
A8: 46116 | B8: Sat | C8: =SUMIFS('02_Meta_Raw_Data'!$J:$J,'02_Meta_Raw_Data'!$A:$A,$A8) | D8: =SUMIFS('02_Meta_Raw_Data'!$P:$P,'02_Meta_Raw_Data'!$A:$A,$A8) | E8: =COUNTIFS('03_Prospects_CRM'!$B:$B,$A8) | F8: =COUNTIFS('03_Prospects_CRM'!$B:$B,$A8,'03_Prospects_CRM'!$T:$T,"MQL")+COUNTIFS('03_Prospects_CRM'!$B:$B,$A8,'03_Prospects_CRM'!$T:$T,"SQL")+COUNTIFS('03_Prospects_CRM'!$B:$B,$A8,'03_Prospects_CRM'!$T:$T,"Deal Won") | G8: =COUNTIFS('03_Prospects_CRM'!$B:$B,$A8,'03_Prospects_CRM'!$T:$T,"SQL")+COUNTIFS('03_Prospects_CRM'!$B:$B,$A8,'03_Prospects_CRM'!$T:$T,"Deal Won") | H8: =COUNTIFS('03_Prospects_CRM'!$B:$B,$A8,'03_Prospects_CRM'!$T:$T,"Deal Won") | I8: =COUNTIFS('03_Prospects_CRM'!$B:$B,$A8,'03_Prospects_CRM'!$T:$T,"Deal Lost") | J8: =SUMIFS('03_Prospects_CRM'!$X:$X,'03_Prospects_CRM'!$B:$B,$A8) | K8: =IFERROR(C8/E8,0) | L8: =IFERROR(C8/F8,0) | M8: =IFERROR(C8/G8,0) | N8: =IFERROR(C8/H8,0) | O8: =IFERROR(J8/C8,0) | P8: =IFERROR(SUMIFS('02_Meta_Raw_Data'!$T:$T,'02_Meta_Raw_Data'!$A:$A,$A8)/D8,0) | Q8: =IFERROR(COUNTIFS('03_Prospects_CRM'!$B:$B,$A8,'03_Prospects_CRM'!$AD:$AD,"Yes")/E8,0)
A9: 46117 | B9: Sun | C9: =SUMIFS('02_Meta_Raw_Data'!$J:$J,'02_Meta_Raw_Data'!$A:$A,$A9) | D9: =SUMIFS('02_Meta_Raw_Data'!$P:$P,'02_Meta_Raw_Data'!$A:$A,$A9) | E9: =COUNTIFS('03_Prospects_CRM'!$B:$B,$A9) | F9: =COUNTIFS('03_Prospects_CRM'!$B:$B,$A9,'03_Prospects_CRM'!$T:$T,"MQL")+COUNTIFS('03_Prospects_CRM'!$B:$B,$A9,'03_Prospects_CRM'!$T:$T,"SQL")+COUNTIFS('03_Prospects_CRM'!$B:$B,$A9,'03_Prospects_CRM'!$T:$T,"Deal Won") | G9: =COUNTIFS('03_Prospects_CRM'!$B:$B,$A9,'03_Prospects_CRM'!$T:$T,"SQL")+COUNTIFS('03_Prospects_CRM'!$B:$B,$A9,'03_Prospects_CRM'!$T:$T,"Deal Won") | H9: =COUNTIFS('03_Prospects_CRM'!$B:$B,$A9,'03_Prospects_CRM'!$T:$T,"Deal Won") | I9: =COUNTIFS('03_Prospects_CRM'!$B:$B,$A9,'03_Prospects_CRM'!$T:$T,"Deal Lost") | J9: =SUMIFS('03_Prospects_CRM'!$X:$X,'03_Prospects_CRM'!$B:$B,$A9) | K9: =IFERROR(C9/E9,0) | L9: =IFERROR(C9/F9,0) | M9: =IFERROR(C9/G9,0) | N9: =IFERROR(C9/H9,0) | O9: =IFERROR(J9/C9,0) | P9: =IFERROR(SUMIFS('02_Meta_Raw_Data'!$T:$T,'02_Meta_Raw_Data'!$A:$A,$A9)/D9,0) | Q9: =IFERROR(COUNTIFS('03_Prospects_CRM'!$B:$B,$A9,'03_Prospects_CRM'!$AD:$AD,"Yes")/E9,0)
A10: 46118 | B10: Mon | C10: =SUMIFS('02_Meta_Raw_Data'!$J:$J,'02_Meta_Raw_Data'!$A:$A,$A10) | D10: =SUMIFS('02_Meta_Raw_Data'!$P:$P,'02_Meta_Raw_Data'!$A:$A,$A10) | E10: =COUNTIFS('03_Prospects_CRM'!$B:$B,$A10) | F10: =COUNTIFS('03_Prospects_CRM'!$B:$B,$A10,'03_Prospects_CRM'!$T:$T,"MQL")+COUNTIFS('03_Prospects_CRM'!$B:$B,$A10,'03_Prospects_CRM'!$T:$T,"SQL")+COUNTIFS('03_Prospects_CRM'!$B:$B,$A10,'03_Prospects_CRM'!$T:$T,"Deal Won") | G10: =COUNTIFS('03_Prospects_CRM'!$B:$B,$A10,'03_Prospects_CRM'!$T:$T,"SQL")+COUNTIFS('03_Prospects_CRM'!$B:$B,$A10,'03_Prospects_CRM'!$T:$T,"Deal Won") | H10: =COUNTIFS('03_Prospects_CRM'!$B:$B,$A10,'03_Prospects_CRM'!$T:$T,"Deal Won") | I10: =COUNTIFS('03_Prospects_CRM'!$B:$B,$A10,'03_Prospects_CRM'!$T:$T,"Deal Lost") | J10: =SUMIFS('03_Prospects_CRM'!$X:$X,'03_Prospects_CRM'!$B:$B,$A10) | K10: =IFERROR(C10/E10,0) | L10: =IFERROR(C10/F10,0) | M10: =IFERROR(C10/G10,0) | N10: =IFERROR(C10/H10,0) | O10: =IFERROR(J10/C10,0) | P10: =IFERROR(SUMIFS('02_Meta_Raw_Data'!$T:$T,'02_Meta_Raw_Data'!$A:$A,$A10)/D10,0) | Q10: =IFERROR(COUNTIFS('03_Prospects_CRM'!$B:$B,$A10,'03_Prospects_CRM'!$AD:$AD,"Yes")/E10,0)
A11: 46119 | B11: Tue | C11: =SUMIFS('02_Meta_Raw_Data'!$J:$J,'02_Meta_Raw_Data'!$A:$A,$A11) | D11: =SUMIFS('02_Meta_Raw_Data'!$P:$P,'02_Meta_Raw_Data'!$A:$A,$A11) | E11: =COUNTIFS('03_Prospects_CRM'!$B:$B,$A11) | F11: =COUNTIFS('03_Prospects_CRM'!$B:$B,$A11,'03_Prospects_CRM'!$T:$T,"MQL")+COUNTIFS('03_Prospects_CRM'!$B:$B,$A11,'03_Prospects_CRM'!$T:$T,"SQL")+COUNTIFS('03_Prospects_CRM'!$B:$B,$A11,'03_Prospects_CRM'!$T:$T,"Deal Won") | G11: =COUNTIFS('03_Prospects_CRM'!$B:$B,$A11,'03_Prospects_CRM'!$T:$T,"SQL")+COUNTIFS('03_Prospects_CRM'!$B:$B,$A11,'03_Prospects_CRM'!$T:$T,"Deal Won") | H11: =COUNTIFS('03_Prospects_CRM'!$B:$B,$A11,'03_Prospects_CRM'!$T:$T,"Deal Won") | I11: =COUNTIFS('03_Prospects_CRM'!$B:$B,$A11,'03_Prospects_CRM'!$T:$T,"Deal Lost") | J11: =SUMIFS('03_Prospects_CRM'!$X:$X,'03_Prospects_CRM'!$B:$B,$A11) | K11: =IFERROR(C11/E11,0) | L11: =IFERROR(C11/F11,0) | M11: =IFERROR(C11/G11,0) | N11: =IFERROR(C11/H11,0) | O11: =IFERROR(J11/C11,0) | P11: =IFERROR(SUMIFS('02_Meta_Raw_Data'!$T:$T,'02_Meta_Raw_Data'!$A:$A,$A11)/D11,0) | Q11: =IFERROR(COUNTIFS('03_Prospects_CRM'!$B:$B,$A11,'03_Prospects_CRM'!$AD:$AD,"Yes")/E11,0)
A12: 46120 | B12: Wed | C12: =SUMIFS('02_Meta_Raw_Data'!$J:$J,'02_Meta_Raw_Data'!$A:$A,$A12) | D12: =SUMIFS('02_Meta_Raw_Data'!$P:$P,'02_Meta_Raw_Data'!$A:$A,$A12) | E12: =COUNTIFS('03_Prospects_CRM'!$B:$B,$A12) | F12: =COUNTIFS('03_Prospects_CRM'!$B:$B,$A12,'03_Prospects_CRM'!$T:$T,"MQL")+COUNTIFS('03_Prospects_CRM'!$B:$B,$A12,'03_Prospects_CRM'!$T:$T,"SQL")+COUNTIFS('03_Prospects_CRM'!$B:$B,$A12,'03_Prospects_CRM'!$T:$T,"Deal Won") | G12: =COUNTIFS('03_Prospects_CRM'!$B:$B,$A12,'03_Prospects_CRM'!$T:$T,"SQL")+COUNTIFS('03_Prospects_CRM'!$B:$B,$A12,'03_Prospects_CRM'!$T:$T,"Deal Won") | H12: =COUNTIFS('03_Prospects_CRM'!$B:$B,$A12,'03_Prospects_CRM'!$T:$T,"Deal Won") | I12: =COUNTIFS('03_Prospects_CRM'!$B:$B,$A12,'03_Prospects_CRM'!$T:$T,"Deal Lost") | J12: =SUMIFS('03_Prospects_CRM'!$X:$X,'03_Prospects_CRM'!$B:$B,$A12) | K12: =IFERROR(C12/E12,0) | L12: =IFERROR(C12/F12,0) | M12: =IFERROR(C12/G12,0) | N12: =IFERROR(C12/H12,0) | O12: =IFERROR(J12/C12,0) | P12: =IFERROR(SUMIFS('02_Meta_Raw_Data'!$T:$T,'02_Meta_Raw_Data'!$A:$A,$A12)/D12,0) | Q12: =IFERROR(COUNTIFS('03_Prospects_CRM'!$B:$B,$A12,'03_Prospects_CRM'!$AD:$AD,"Yes")/E12,0)
A13: 46121 | B13: Thu | C13: =SUMIFS('02_Meta_Raw_Data'!$J:$J,'02_Meta_Raw_Data'!$A:$A,$A13) | D13: =SUMIFS('02_Meta_Raw_Data'!$P:$P,'02_Meta_Raw_Data'!$A:$A,$A13) | E13: =COUNTIFS('03_Prospects_CRM'!$B:$B,$A13) | F13: =COUNTIFS('03_Prospects_CRM'!$B:$B,$A13,'03_Prospects_CRM'!$T:$T,"MQL")+COUNTIFS('03_Prospects_CRM'!$B:$B,$A13,'03_Prospects_CRM'!$T:$T,"SQL")+COUNTIFS('03_Prospects_CRM'!$B:$B,$A13,'03_Prospects_CRM'!$T:$T,"Deal Won") | G13: =COUNTIFS('03_Prospects_CRM'!$B:$B,$A13,'03_Prospects_CRM'!$T:$T,"SQL")+COUNTIFS('03_Prospects_CRM'!$B:$B,$A13,'03_Prospects_CRM'!$T:$T,"Deal Won") | H13: =COUNTIFS('03_Prospects_CRM'!$B:$B,$A13,'03_Prospects_CRM'!$T:$T,"Deal Won") | I13: =COUNTIFS('03_Prospects_CRM'!$B:$B,$A13,'03_Prospects_CRM'!$T:$T,"Deal Lost") | J13: =SUMIFS('03_Prospects_CRM'!$X:$X,'03_Prospects_CRM'!$B:$B,$A13) | K13: =IFERROR(C13/E13,0) | L13: =IFERROR(C13/F13,0) | M13: =IFERROR(C13/G13,0) | N13: =IFERROR(C13/H13,0) | O13: =IFERROR(J13/C13,0) | P13: =IFERROR(SUMIFS('02_Meta_Raw_Data'!$T:$T,'02_Meta_Raw_Data'!$A:$A,$A13)/D13,0) | Q13: =IFERROR(COUNTIFS('03_Prospects_CRM'!$B:$B,$A13,'03_Prospects_CRM'!$AD:$AD,"Yes")/E13,0)
A14: 46122 | B14: Fri | C14: =SUMIFS('02_Meta_Raw_Data'!$J:$J,'02_Meta_Raw_Data'!$A:$A,$A14) | D14: =SUMIFS('02_Meta_Raw_Data'!$P:$P,'02_Meta_Raw_Data'!$A:$A,$A14) | E14: =COUNTIFS('03_Prospects_CRM'!$B:$B,$A14) | F14: =COUNTIFS('03_Prospects_CRM'!$B:$B,$A14,'03_Prospects_CRM'!$T:$T,"MQL")+COUNTIFS('03_Prospects_CRM'!$B:$B,$A14,'03_Prospects_CRM'!$T:$T,"SQL")+COUNTIFS('03_Prospects_CRM'!$B:$B,$A14,'03_Prospects_CRM'!$T:$T,"Deal Won") | G14: =COUNTIFS('03_Prospects_CRM'!$B:$B,$A14,'03_Prospects_CRM'!$T:$T,"SQL")+COUNTIFS('03_Prospects_CRM'!$B:$B,$A14,'03_Prospects_CRM'!$T:$T,"Deal Won") | H14: =COUNTIFS('03_Prospects_CRM'!$B:$B,$A14,'03_Prospects_CRM'!$T:$T,"Deal Won") | I14: =COUNTIFS('03_Prospects_CRM'!$B:$B,$A14,'03_Prospects_CRM'!$T:$T,"Deal Lost") | J14: =SUMIFS('03_Prospects_CRM'!$X:$X,'03_Prospects_CRM'!$B:$B,$A14) | K14: =IFERROR(C14/E14,0) | L14: =IFERROR(C14/F14,0) | M14: =IFERROR(C14/G14,0) | N14: =IFERROR(C14/H14,0) | O14: =IFERROR(J14/C14,0) | P14: =IFERROR(SUMIFS('02_Meta_Raw_Data'!$T:$T,'02_Meta_Raw_Data'!$A:$A,$A14)/D14,0) | Q14: =IFERROR(COUNTIFS('03_Prospects_CRM'!$B:$B,$A14,'03_Prospects_CRM'!$AD:$AD,"Yes")/E14,0)
A15: 46123 | B15: Sat | C15: =SUMIFS('02_Meta_Raw_Data'!$J:$J,'02_Meta_Raw_Data'!$A:$A,$A15) | D15: =SUMIFS('02_Meta_Raw_Data'!$P:$P,'02_Meta_Raw_Data'!$A:$A,$A15) | E15: =COUNTIFS('03_Prospects_CRM'!$B:$B,$A15) | F15: =COUNTIFS('03_Prospects_CRM'!$B:$B,$A15,'03_Prospects_CRM'!$T:$T,"MQL")+COUNTIFS('03_Prospects_CRM'!$B:$B,$A15,'03_Prospects_CRM'!$T:$T,"SQL")+COUNTIFS('03_Prospects_CRM'!$B:$B,$A15,'03_Prospects_CRM'!$T:$T,"Deal Won") | G15: =COUNTIFS('03_Prospects_CRM'!$B:$B,$A15,'03_Prospects_CRM'!$T:$T,"SQL")+COUNTIFS('03_Prospects_CRM'!$B:$B,$A15,'03_Prospects_CRM'!$T:$T,"Deal Won") | H15: =COUNTIFS('03_Prospects_CRM'!$B:$B,$A15,'03_Prospects_CRM'!$T:$T,"Deal Won") | I15: =COUNTIFS('03_Prospects_CRM'!$B:$B,$A15,'03_Prospects_CRM'!$T:$T,"Deal Lost") | J15: =SUMIFS('03_Prospects_CRM'!$X:$X,'03_Prospects_CRM'!$B:$B,$A15) | K15: =IFERROR(C15/E15,0) | L15: =IFERROR(C15/F15,0) | M15: =IFERROR(C15/G15,0) | N15: =IFERROR(C15/H15,0) | O15: =IFERROR(J15/C15,0) | P15: =IFERROR(SUMIFS('02_Meta_Raw_Data'!$T:$T,'02_Meta_Raw_Data'!$A:$A,$A15)/D15,0) | Q15: =IFERROR(COUNTIFS('03_Prospects_CRM'!$B:$B,$A15,'03_Prospects_CRM'!$AD:$AD,"Yes")/E15,0)
A16: 46124 | B16: Sun | C16: =SUMIFS('02_Meta_Raw_Data'!$J:$J,'02_Meta_Raw_Data'!$A:$A,$A16) | D16: =SUMIFS('02_Meta_Raw_Data'!$P:$P,'02_Meta_Raw_Data'!$A:$A,$A16) | E16: =COUNTIFS('03_Prospects_CRM'!$B:$B,$A16) | F16: =COUNTIFS('03_Prospects_CRM'!$B:$B,$A16,'03_Prospects_CRM'!$T:$T,"MQL")+COUNTIFS('03_Prospects_CRM'!$B:$B,$A16,'03_Prospects_CRM'!$T:$T,"SQL")+COUNTIFS('03_Prospects_CRM'!$B:$B,$A16,'03_Prospects_CRM'!$T:$T,"Deal Won") | G16: =COUNTIFS('03_Prospects_CRM'!$B:$B,$A16,'03_Prospects_CRM'!$T:$T,"SQL")+COUNTIFS('03_Prospects_CRM'!$B:$B,$A16,'03_Prospects_CRM'!$T:$T,"Deal Won") | H16: =COUNTIFS('03_Prospects_CRM'!$B:$B,$A16,'03_Prospects_CRM'!$T:$T,"Deal Won") | I16: =COUNTIFS('03_Prospects_CRM'!$B:$B,$A16,'03_Prospects_CRM'!$T:$T,"Deal Lost") | J16: =SUMIFS('03_Prospects_CRM'!$X:$X,'03_Prospects_CRM'!$B:$B,$A16) | K16: =IFERROR(C16/E16,0) | L16: =IFERROR(C16/F16,0) | M16: =IFERROR(C16/G16,0) | N16: =IFERROR(C16/H16,0) | O16: =IFERROR(J16/C16,0) | P16: =IFERROR(SUMIFS('02_Meta_Raw_Data'!$T:$T,'02_Meta_Raw_Data'!$A:$A,$A16)/D16,0) | Q16: =IFERROR(COUNTIFS('03_Prospects_CRM'!$B:$B,$A16,'03_Prospects_CRM'!$AD:$AD,"Yes")/E16,0)
... A95: 46203 | B95: Tue | C95: =SUMIFS('02_Meta_Raw_Data'!$J:$J,'02_Meta_Raw_Data'!$A:$A,$A95) | D95: =SUMIFS('02_Meta_Raw_Data'!$P:$P,'02_Meta_Raw_Data'!$A:$A,$A95) | E95: =COUNTIFS('03_Prospects_CRM'!$B:$B,$A95) | F95: =COUNTIFS('03_Prospects_CRM'!$B:$B,$A95,'03_Prospects_CRM'!$T:$T,"MQL")+COUNTIFS('03_Prospects_CRM'!$B:$B,$A95,'03_Prospects_CRM'!$T:$T,"SQL")+COUNTIFS('03_Prospects_CRM'!$B:$B,$A95,'03_Prospects_CRM'!$T:$T,"Deal Won") | G95: =COUNTIFS('03_Prospects_CRM'!$B:$B,$A95,'03_Prospects_CRM'!$T:$T,"SQL")+COUNTIFS('03_Prospects_CRM'!$B:$B,$A95,'03_Prospects_CRM'!$T:$T,"Deal Won") | H95: =COUNTIFS('03_Prospects_CRM'!$B:$B,$A95,'03_Prospects_CRM'!$T:$T,"Deal Won") | I95: =COUNTIFS('03_Prospects_CRM'!$B:$B,$A95,'03_Prospects_CRM'!$T:$T,"Deal Lost") | J95: =SUMIFS('03_Prospects_CRM'!$X:$X,'03_Prospects_CRM'!$B:$B,$A95) | K95: =IFERROR(C95/E95,0) | L95: =IFERROR(C95/F95,0) | M95: =IFERROR(C95/G95,0) | N95: =IFERROR(C95/H95,0) | O95: =IFERROR(J95/C95,0) | P95: =IFERROR(SUMIFS('02_Meta_Raw_Data'!$T:$T,'02_Meta_Raw_Data'!$A:$A,$A95)/D95,0) | Q95: =IFERROR(COUNTIFS('03_Prospects_CRM'!$B:$B,$A95,'03_Prospects_CRM'!$AD:$AD,"Yes")/E95,0)

Sheet 06_Merged_Performance
A1: 06 | Merged Performance
A2: Daily/ad-level merged performance with Meta cost and CRM outcomes.
A4: Date | B4: Campaign ID | C4: Campaign Name | D4: Ad Set ID | E4: Ad Set Name | F4: Ad ID | G4: Ad Name | H4: Spend | I4: Conversations | J4: CRM Leads | K4: MQL | L4: SQL | M4: Deals Won | N4: Deals Lost | O4: Revenue | P4: CPL | Q4: Cost/MQL | R4: Cost/SQL | S4: CAC | T4: ROAS
A5: 46113 | B5: CMP-001 | C5: In2out - MessCampaign#1 - Testing - 15/4 | D5: AS-0101 | E5: In2out - MessCampaign#1 - Testing - 15/4 | Broad SMEs | F5: AD-010101 | G5: Pain Point Static | Broad SMEs | H5: 263.21 | I5: 37 | J5: 2 | K5: 0 | L5: 0 | M5: 0 | N5: 1 | O5: 0 | P5: 131.6 | Q5: 0 | R5: 0 | S5: 0 | T5: 0
A6: 46113 | B6: CMP-001 | C6: In2out - MessCampaign#1 - Testing - 15/4 | D6: AS-0101 | E6: In2out - MessCampaign#1 - Testing - 15/4 | Broad SMEs | F6: AD-010102 | G6: Demo Reel | Broad SMEs | H6: 166.01 | I6: 15 | J6: 2 | K6: 0 | L6: 0 | M6: 0 | N6: 1 | O6: 0 | P6: 83 | Q6: 0 | R6: 0 | S6: 0 | T6: 0
A7: 46113 | B7: CMP-001 | C7: In2out - MessCampaign#1 - Testing - 15/4 | D7: AS-0101 | E7: In2out - MessCampaign#1 - Testing - 15/4 | Broad SMEs | F7: AD-010103 | G7: Offer Carousel | Broad SMEs | H7: 301.64 | I7: 29 | J7: 1 | K7: 0 | L7: 0 | M7: 0 | N7: 0 | O7: 0 | P7: 301.64 | Q7: 0 | R7: 0 | S7: 0 | T7: 0
A8: 46113 | B8: CMP-001 | C8: In2out - MessCampaign#1 - Testing - 15/4 | D8: AS-0102 | E8: In2out - MessCampaign#1 - Testing - 15/4 | Interest Tax Owners | F8: AD-010201 | G8: Pain Point Static | Interest Tax Owners | H8: 301.95 | I8: 39 | J8: 2 | K8: 0 | L8: 0 | M8: 0 | N8: 0 | O8: 0 | P8: 150.97 | Q8: 0 | R8: 0 | S8: 0 | T8: 0
A9: 46113 | B9: CMP-001 | C9: In2out - MessCampaign#1 - Testing - 15/4 | D9: AS-0102 | E9: In2out - MessCampaign#1 - Testing - 15/4 | Interest Tax Owners | F9: AD-010202 | G9: Demo Reel | Interest Tax Owners | H9: 278.26 | I9: 22 | J9: 0 | K9: 0 | L9: 0 | M9: 0 | N9: 0 | O9: 0 | P9: 0 | Q9: 0 | R9: 0 | S9: 0 | T9: 0
A10: 46113 | B10: CMP-002 | C10: In2out - MessCampaign#2 - Testing - 20/4 | D10: AS-0201 | E10: In2out - MessCampaign#2 - Testing - 20/4 | Broad SMEs | F10: AD-020101 | G10: Pain Point Static | Broad SMEs | H10: 201.01 | I10: 30 | J10: 2 | K10: 0 | L10: 0 | M10: 0 | N10: 0 | O10: 0 | P10: 100.5 | Q10: 0 | R10: 0 | S10: 0 | T10: 0
A11: 46113 | B11: CMP-002 | C11: In2out - MessCampaign#2 - Testing - 20/4 | D11: AS-0201 | E11: In2out - MessCampaign#2 - Testing - 20/4 | Broad SMEs | F11: AD-020102 | G11: Demo Reel | Broad SMEs | H11: 344.08 | I11: 37 | J11: 1 | K11: 0 | L11: 0 | M11: 0 | N11: 0 | O11: 0 | P11: 344.08 | Q11: 0 | R11: 0 | S11: 0 | T11: 0
A12: 46113 | B12: CMP-002 | C12: In2out - MessCampaign#2 - Testing - 20/4 | D12: AS-0201 | E12: In2out - MessCampaign#2 - Testing - 20/4 | Broad SMEs | F12: AD-020103 | G12: Offer Carousel | Broad SMEs | H12: 164.24 | I12: 9 | J12: 4 | K12: 1 | L12: 0 | M12: 0 | N12: 0 | O12: 0 | P12: 41.06 | Q12: 164.24 | R12: 0 | S12: 0 | T12: 0
A13: 46113 | B13: CMP-002 | C13: In2out - MessCampaign#2 - Testing - 20/4 | D13: AS-0202 | E13: In2out - MessCampaign#2 - Testing - 20/4 | Interest Tax Owners | F13: AD-020201 | G13: Pain Point Static | Interest Tax Owners | H13: 245.18 | I13: 27 | J13: 0 | K13: 0 | L13: 0 | M13: 0 | N13: 0 | O13: 0 | P13: 0 | Q13: 0 | R13: 0 | S13: 0 | T13: 0
A14: 46113 | B14: CMP-002 | C14: In2out - MessCampaign#2 - Testing - 20/4 | D14: AS-0202 | E14: In2out - MessCampaign#2 - Testing - 20/4 | Interest Tax Owners | F14: AD-020202 | G14: Demo Reel | Interest Tax Owners | H14: 140.83 | I14: 5 | J14: 1 | K14: 0 | L14: 0 | M14: 0 | N14: 0 | O14: 0 | P14: 140.83 | Q14: 0 | R14: 0 | S14: 0 | T14: 0
A15: 46113 | B15: CMP-003 | C15: Mofawtar - E-Receipt - Awareness - Q2 | D15: AS-0301 | E15: Mofawtar - E-Receipt - Awareness - Q2 | Broad SMEs | F15: AD-030101 | G15: Pain Point Static | Broad SMEs | H15: 118.15 | I15: 7 | J15: 2 | K15: 0 | L15: 0 | M15: 0 | N15: 0 | O15: 0 | P15: 59.08 | Q15: 0 | R15: 0 | S15: 0 | T15: 0
A16: 46113 | B16: CMP-003 | C16: Mofawtar - E-Receipt - Awareness - Q2 | D16: AS-0301 | E16: Mofawtar - E-Receipt - Awareness - Q2 | Broad SMEs | F16: AD-030102 | G16: Demo Reel | Broad SMEs | H16: 317.82 | I16: 28 | J16: 0 | K16: 0 | L16: 0 | M16: 0 | N16: 0 | O16: 0 | P16: 0 | Q16: 0 | R16: 0 | S16: 0 | T16: 0
... A2643: 46203 | B2643: CMP-005 | C2643: Mofawtar - Retargeting - Demo Booking - Q2 | D2643: AS-0503 | E2643: Mofawtar - Retargeting - Demo Booking - Q2 | Retargeting Visitors | F2643: AD-050302 | G2643: Demo Reel | Retargeting Visitors | H2643: 247.03 | I2643: 30 | J2643: 0 | K2643: 0 | L2643: 0 | M2643: 0 | N2643: 0 | O2643: 0 | P2643: 0 | Q2643: 0 | R2643: 0 | S2643: 0 | T2643: 0

Sheet 07_Campaign_Summary
A1: 07 Campaign Summary
A2: Campaign rollup: cost, funnel and revenue.
A4: ID | B4: Name | C4: Spend | D4: Conversations | E4: CRM Leads | F4: MQL | G4: SQL | H4: Deals Won | I4: Deals Lost | J4: Revenue | K4: CPL | L4: Cost/MQL | M4: Cost/SQL | N4: CAC | O4: ROAS | P4: Lead→MQL | Q4: MQL→SQL | R4: SQL→Deal
A5: CMP-001 | B5: In2out - MessCampaign#1 - Testing - 15/4 | C5: =SUMIFS('02_Meta_Raw_Data'!$J:$J,'02_Meta_Raw_Data'!$B:$B,$A5) | D5: =SUMIFS('02_Meta_Raw_Data'!$P:$P,'02_Meta_Raw_Data'!$B:$B,$A5) | E5: =COUNTIFS('03_Prospects_CRM'!$L:$L,$A5) | F5: =COUNTIFS('03_Prospects_CRM'!$L:$L,$A5,'03_Prospects_CRM'!$T:$T,"MQL")+COUNTIFS('03_Prospects_CRM'!$L:$L,$A5,'03_Prospects_CRM'!$T:$T,"SQL")+COUNTIFS('03_Prospects_CRM'!$L:$L,$A5,'03_Prospects_CRM'!$T:$T,"Deal Won") | G5: =COUNTIFS('03_Prospects_CRM'!$L:$L,$A5,'03_Prospects_CRM'!$T:$T,"SQL")+COUNTIFS('03_Prospects_CRM'!$L:$L,$A5,'03_Prospects_CRM'!$T:$T,"Deal Won") | H5: =COUNTIFS('03_Prospects_CRM'!$L:$L,$A5,'03_Prospects_CRM'!$T:$T,"Deal Won") | I5: =COUNTIFS('03_Prospects_CRM'!$L:$L,$A5,'03_Prospects_CRM'!$T:$T,"Deal Lost") | J5: =SUMIFS('03_Prospects_CRM'!$X:$X,'03_Prospects_CRM'!$L:$L,$A5) | K5: =IFERROR(C5/E5,0) | L5: =IFERROR(C5/F5,0) | M5: =IFERROR(C5/G5,0) | N5: =IFERROR(C5/H5,0) | O5: =IFERROR(J5/C5,0) | P5: =IFERROR(F5/E5,0) | Q5: =IFERROR(G5/F5,0) | R5: =IFERROR(H5/G5,0)
A6: CMP-002 | B6: In2out - MessCampaign#2 - Testing - 20/4 | C6: =SUMIFS('02_Meta_Raw_Data'!$J:$J,'02_Meta_Raw_Data'!$B:$B,$A6) | D6: =SUMIFS('02_Meta_Raw_Data'!$P:$P,'02_Meta_Raw_Data'!$B:$B,$A6) | E6: =COUNTIFS('03_Prospects_CRM'!$L:$L,$A6) | F6: =COUNTIFS('03_Prospects_CRM'!$L:$L,$A6,'03_Prospects_CRM'!$T:$T,"MQL")+COUNTIFS('03_Prospects_CRM'!$L:$L,$A6,'03_Prospects_CRM'!$T:$T,"SQL")+COUNTIFS('03_Prospects_CRM'!$L:$L,$A6,'03_Prospects_CRM'!$T:$T,"Deal Won") | G6: =COUNTIFS('03_Prospects_CRM'!$L:$L,$A6,'03_Prospects_CRM'!$T:$T,"SQL")+COUNTIFS('03_Prospects_CRM'!$L:$L,$A6,'03_Prospects_CRM'!$T:$T,"Deal Won") | H6: =COUNTIFS('03_Prospects_CRM'!$L:$L,$A6,'03_Prospects_CRM'!$T:$T,"Deal Won") | I6: =COUNTIFS('03_Prospects_CRM'!$L:$L,$A6,'03_Prospects_CRM'!$T:$T,"Deal Lost") | J6: =SUMIFS('03_Prospects_CRM'!$X:$X,'03_Prospects_CRM'!$L:$L,$A6) | K6: =IFERROR(C6/E6,0) | L6: =IFERROR(C6/F6,0) | M6: =IFERROR(C6/G6,0) | N6: =IFERROR(C6/H6,0) | O6: =IFERROR(J6/C6,0) | P6: =IFERROR(F6/E6,0) | Q6: =IFERROR(G6/F6,0) | R6: =IFERROR(H6/G6,0)
A7: CMP-003 | B7: Mofawtar - E-Receipt - Awareness - Q2 | C7: =SUMIFS('02_Meta_Raw_Data'!$J:$J,'02_Meta_Raw_Data'!$B:$B,$A7) | D7: =SUMIFS('02_Meta_Raw_Data'!$P:$P,'02_Meta_Raw_Data'!$B:$B,$A7) | E7: =COUNTIFS('03_Prospects_CRM'!$L:$L,$A7) | F7: =COUNTIFS('03_Prospects_CRM'!$L:$L,$A7,'03_Prospects_CRM'!$T:$T,"MQL")+COUNTIFS('03_Prospects_CRM'!$L:$L,$A7,'03_Prospects_CRM'!$T:$T,"SQL")+COUNTIFS('03_Prospects_CRM'!$L:$L,$A7,'03_Prospects_CRM'!$T:$T,"Deal Won") | G7: =COUNTIFS('03_Prospects_CRM'!$L:$L,$A7,'03_Prospects_CRM'!$T:$T,"SQL")+COUNTIFS('03_Prospects_CRM'!$L:$L,$A7,'03_Prospects_CRM'!$T:$T,"Deal Won") | H7: =COUNTIFS('03_Prospects_CRM'!$L:$L,$A7,'03_Prospects_CRM'!$T:$T,"Deal Won") | I7: =COUNTIFS('03_Prospects_CRM'!$L:$L,$A7,'03_Prospects_CRM'!$T:$T,"Deal Lost") | J7: =SUMIFS('03_Prospects_CRM'!$X:$X,'03_Prospects_CRM'!$L:$L,$A7) | K7: =IFERROR(C7/E7,0) | L7: =IFERROR(C7/F7,0) | M7: =IFERROR(C7/G7,0) | N7: =IFERROR(C7/H7,0) | O7: =IFERROR(J7/C7,0) | P7: =IFERROR(F7/E7,0) | Q7: =IFERROR(G7/F7,0) | R7: =IFERROR(H7/G7,0)
